Workbook
Name h_TVA: 'Hypothèses'!$C$6
Name h_IS_TAUX_REDUIT: 'Hypothèses'!$C$7
Name h_IS_SEUIL: 'Hypothèses'!$C$8
Name h_IS_TAUX_NORMAL: 'Hypothèses'!$C$9
Name h_FRANCHISE_SEUIL: 'Hypothèses'!$C$10
Name h_FRANCHISE_SEUIL_MAJORE: 'Hypothèses'!$C$11
Name h_MICRO_COTIS: 'Hypothèses'!$C$12
Name h_MICRO_VL: 'Hypothèses'!$C$13
Name h_MICRO_PLAFOND: 'Hypothèses'!$C$14
Name h_PFU: 'Hypothèses'!$C$15
Name h_CHARGES_SASU: 'Hypothèses'!$C$16
Name h_CHARGES_TNS: 'Hypothèses'!$C$17
Name h_TNS_MINIMUM: 'Hypothèses'!$C$18
Name h_SMIC_NET_H: 'Hypothèses'!$C$19
Name h_HEURES_FONDATEUR: 'Hypothèses'!$C$20
Name h_TAP_PRIX: 'Hypothèses'!$C$22
Name h_TAP_PROD: 'Hypothèses'!$C$23
Name h_TAP_DROITS: 'Hypothèses'!$C$24
Name h_TAP_POIDS: 'Hypothèses'!$C$25
Name h_RAC_PRIX: 'Hypothèses'!$C$27
Name h_RAC_PROD: 'Hypothèses'!$C$28
Name h_RAC_DROITS: 'Hypothèses'!$C$29
Name h_RAC_POIDS: 'Hypothèses'!$C$30
Name h_GAN_PRIX: 'Hypothèses'!$C$32
Name h_GAN_PROD: 'Hypothèses'!$C$33
Name h_GAN_DROITS: 'Hypothèses'!$C$34
Name h_GAN_POIDS: 'Hypothèses'!$C$35
Name h_ROU_PRIX: 'Hypothèses'!$C$37
Name h_ROU_PROD: 'Hypothèses'!$C$38
Name h_ROU_DROITS: 'Hypothèses'!$C$39
Name h_ROU_POIDS: 'Hypothèses'!$C$40
Name h_KAP_PRIX: 'Hypothèses'!$C$42
Name h_GK_PRIX: 'Hypothèses'!$C$43
Name h_DUO_PRIX: 'Hypothèses'!$C$44
Name h_HIV_PRIX: 'Hypothèses'!$C$45
Name h_PORT_CLIENT_TTC: 'Hypothèses'!$C$47
Name h_SEUIL_GRATUIT: 'Hypothèses'!$C$48
Name h_PORT_500: 'Hypothèses'!$C$49
Name h_PORT_1KG: 'Hypothèses'!$C$50
Name h_PORT_2KG: 'Hypothèses'!$C$51
Name h_EMB_PETIT: 'Hypothèses'!$C$52
Name h_EMB_GRAND: 'Hypothèses'!$C$53
Name h_STRIPE_PCT: 'Hypothèses'!$C$54
Name h_STRIPE_FIXE: 'Hypothèses'!$C$55
Name h_STRIPE_LITIGE: 'Hypothèses'!$C$56
Name h_PAYPAL_PCT: 'Hypothèses'!$C$57
Name h_PAYPAL_FIXE: 'Hypothèses'!$C$58
Name h_TTS_COMM: 'Hypothèses'!$C$59
Name h_TTS_COMM_LANCEMENT: 'Hypothèses'!$C$60
Name h_CREA_COMM: 'Hypothèses'!$C$61
Name h_PROV_RETOURS: 'Hypothèses'!$C$62
Name h_MIX_AFF: 'Hypothèses'!$C$64
Name h_MIX_PROPRE: 'Hypothèses'!$C$65
Name h_MIX_SITE: 'Hypothèses'!$C$66
Name h_SITE_ROU: 'Hypothèses'!$C$67
Name h_SITE_KAP: 'Hypothèses'!$C$68
Name h_SITE_GK: 'Hypothèses'!$C$69
Name h_SITE_DUO: 'Hypothèses'!$C$70
Name h_TTS_ROU: 'Hypothèses'!$C$71
Name h_TTS_KAP: 'Hypothèses'!$C$72

Sheet Hypothèses
A1: Canapoil — hypothèses du modèle financier
A2: Toutes les valeurs en bleu sont des saisies ; chaque cellule de la colonne C porte un nom défini « h_NOM » utilisé par les autres onglets. Prix et coûts produits = brand.json.
A4: Nom Excel | B4: Hypothèse | C4: Valeur | D4: Unité | E4: Source / confiance
A5: Fiscalité
A6: h_TVA | B6: Taux normal de TVA | C6: 0.2 | D6: % | E6: 03 §3.1 ; https://entreprendre.service-public.gouv.fr/vosdroits/F21746 (vérifié le 01/01/2026)
A7: h_IS_TAUX_REDUIT | B7: IS, taux réduit PME | C7: 0.15 | D7: % | E7: https://entreprendre.service-public.gouv.fr/vosdroits/F23575 ; LF 2026 inchangée : https://hayot-expertise.fr/blog/is-2026-taux-normal-taux-reduit-15-seuils
A8: h_IS_SEUIL | B8: IS, plafond du bénéfice au taux réduit | C8: 42500 | D8: € / exercice | E8: https://entreprendre.service-public.gouv.fr/vosdroits/F23575 ; LF 2026 inchangée : https://hayot-expertise.fr/blog/is-2026-taux-normal-taux-reduit-15-seuils
A9: h_IS_TAUX_NORMAL | B9: IS, taux normal | C9: 0.25 | D9: % | E9: https://entreprendre.service-public.gouv.fr/vosdroits/F23575 ; LF 2026 inchangée : https://hayot-expertise.fr/blog/is-2026-taux-normal-taux-reduit-15-seuils
A10: h_FRANCHISE_SEUIL | B10: Franchise en base de TVA : seuil (CA N-1, ventes) | C10: 85000 | D10: € / an | E10: https://entreprendre.service-public.gouv.fr/vosdroits/F21746 (vérifié le 01/01/2026)
A11: h_FRANCHISE_SEUIL_MAJORE | B11: Franchise en base de TVA : seuil majoré (année en cours) | C11: 93500 | D11: € / an | E11: https://entreprendre.service-public.gouv.fr/vosdroits/F21746 (vérifié le 01/01/2026)
A12: h_MICRO_COTIS | B12: Micro-entreprise : cotisations sociales (ventes) | C12: 0.123 | D12: % du CA | E12: https://entreprendre.service-public.gouv.fr/vosdroits/F32353 (03 §3.6)
A13: h_MICRO_VL | B13: Micro-entreprise : versement libératoire (ventes) | C13: 0.01 | D13: % du CA | E13: https://entreprendre.service-public.gouv.fr/vosdroits/F32353 (03 §3.6)
A14: h_MICRO_PLAFOND | B14: Micro-entreprise : plafond de CA (ventes) | C14: 203100 | D14: € / an | E14: https://entreprendre.service-public.gouv.fr/vosdroits/F32353 (03 §3.6)
A15: h_PFU | B15: Prélèvement forfaitaire unique sur dividendes 2026 (12,8 % + 18,6 %) | C15: 0.314 | D15: % | E15: https://www.lafinancepourtous.com/2025/12/17/csg-un-taux-a-double-vitesse-pour-2026/
A16: h_CHARGES_SASU | B16: Président de SASU : cotisations / salaire net | C16: 0.8 | D16: ratio | E16: Fourchette 75-82 % : https://hayot-expertise.fr/blog/charges-sociales-sasu ; https://www.keobiz.fr/le-mag/sasu-charge-sociale/
A17: h_CHARGES_TNS | B17: Gérant majoritaire d'EURL (TNS) : cotisations / rémunération nette | C17: 0.45 | D17: ratio | E17: Fourchette 33-45 % : https://hayot-expertise.fr/blog/charges-sociales-sasu ; https://www.keobiz.fr/le-mag/sasu-charge-sociale/
... A20: h_HEURES_FONDATEUR | B20: Temps du fondateur | C20: 22.5 | D20: h / semaine | E20: 04 §7 risque 8 : 20-25 h par semaine
A21: Produit CNP-TAP-01 — Tapis de fenêtre thermique (brand.json)
A22: h_TAP_PRIX | B22: Prix de vente | C22: 24.9 | D22: € TTC | E22: strategie/brand.json (12/10/2026)
A23: h_TAP_PROD | B23: Coût produit rendu France (produit + fret entrant) | C23: 5 | D23: € HT | E23: strategie/brand.json (12/10/2026) cout_produit_ht
A24: h_TAP_DROITS | B24: Droits et redevance répartis sur le lot | C24: 0.35 | D24: € HT | E24: strategie/brand.json (12/10/2026) droits_douane_estimes
A25: h_TAP_POIDS | B25: Poids | C25: 400 | D25: g | E25: strategie/brand.json (12/10/2026) poids_g
A26: Produit CNP-RAC-01 — Raclette anti-poils (brand.json)
A27: h_RAC_PRIX | B27: Prix de vente | C27: 12.9 | D27: € TTC | E27: strategie/brand.json (12/10/2026)
A28: h_RAC_PROD | B28: Coût produit rendu France (produit + fret entrant) | C28: 1.9 | D28: € HT | E28: strategie/brand.json (12/10/2026) cout_produit_ht
A29: h_RAC_DROITS | B29: Droits et redevance répartis sur le lot | C29: 0.15 | D29: € HT | E29: strategie/brand.json (12/10/2026) droits_douane_estimes
A30: h_RAC_POIDS | B30: Poids | C30: 150 | D30: g | E30: strategie/brand.json (12/10/2026) poids_g
A31: Produit CNP-GAN-01 — Gant de toilettage (brand.json)
A32: h_GAN_PRIX | B32: Prix de vente | C32: 9.9 | D32: € TTC | E32: strategie/brand.json (12/10/2026)
A33: h_GAN_PROD | B33: Coût produit rendu France (produit + fret entrant) | C33: 1.3 | D33: € HT | E33: strategie/brand.json (12/10/2026) cout_produit_ht
A34: h_GAN_DROITS | B34: Droits et redevance répartis sur le lot | C34: 0.1 | D34: € HT | E34: strategie/brand.json (12/10/2026) droits_douane_estimes
A35: h_GAN_POIDS | B35: Poids | C35: 70 | D35: g | E35: strategie/brand.json (12/10/2026) poids_g
A36: Produit CNP-ROU-01 — Rouleau anti-poils (brand.json)
A37: h_ROU_PRIX | B37: Prix de vente | C37: 24.9 | D37: € TTC | E37: strategie/brand.json (12/10/2026)
A38: h_ROU_PROD | B38: Coût produit rendu France (produit + fret entrant) | C38: 4.5 | D38: € HT | E38: strategie/brand.json (12/10/2026) cout_produit_ht
A39: h_ROU_DROITS | B39: Droits et redevance répartis sur le lot | C39: 0.25 | D39: € HT | E39: strategie/brand.json (12/10/2026) droits_douane_estimes
A40: h_ROU_POIDS | B40: Poids | C40: 280 | D40: g | E40: strategie/brand.json (12/10/2026) poids_g
A41: Kits (brand.json)
A42: h_KAP_PRIX | B42: Kit anti-poils : prix | C42: 29.9 | D42: € TTC | E42: strategie/brand.json (12/10/2026) bundles
A43: h_GK_PRIX | B43: Grand kit : prix | C43: 39.9 | D43: € TTC | E43: strategie/brand.json (12/10/2026) bundles
...

Sheet Unit economics
A1: Unit economics par commande (€)
A2: Marge de contribution = CA HT − coûts variables (produit, droits, livraison, paiement, commissions, provision 5 % du CA HT). En franchise et en micro-entreprise, le CA est le prix payé et les coûts portent la TVA non récupérable (×1,2), sauf les frais de paiement.
A4: Société assujettie à la TVA (SASU ou EURL à l'IS) — micro-stock en France (lancement)
A5: Cas | B5: Canal | C5: Poids (g) | D5: Prix payé TTC | E5: TVA collectée | F5: CA HT (base) | G5: Coût produit | H5: Droits de douane | I5: Livraison + emballage | J5: Frais de paiement | K5: Commission TikTok Shop | L5: Commission créateur ou pub | M5: Provision retours / litiges | N5: Cotisations micro | O5: Marge de contribution | P5: % du CA HT | Q5: ROAS de rentabilité HT | R5: ROAS de rentabilité TTC | S5: CPA maximal
A6: Site — Rouleau seul (+3,90 € de port) | B6: Site | C6: =h_ROU_POIDS | D6: =h_ROU_PRIX+IF(h_ROU_PRIX<h_SEUIL_GRATUIT,h_PORT_CLIENT_TTC,0) | E6: =D6-D6/(1+h_TVA) | F6: =D6-E6 | G6: =(h_ROU_PROD) | H6: =(h_ROU_DROITS) | I6: =IF(C6<=500,h_PORT_500+h_EMB_PETIT,IF(C6<=1000,h_PORT_1KG+h_EMB_GRAND,h_PORT_2KG+h_EMB_GRAND)) | J6: =h_STRIPE_PCT*D6+h_STRIPE_FIXE | K6: =0 | L6: =0 | M6: =h_PROV_RETOURS*F6 | N6: =0 | O6: =F6-SUM(G6:N6) | P6: =O6/F6 | Q6: =F6/O6 | R6: =D6/O6 | S6: =O6
A7: Site — Gant seul (+3,90 € de port) | B7: Site | C7: =h_GAN_POIDS | D7: =h_GAN_PRIX+IF(h_GAN_PRIX<h_SEUIL_GRATUIT,h_PORT_CLIENT_TTC,0) | E7: =D7-D7/(1+h_TVA) | F7: =D7-E7 | G7: =(h_GAN_PROD) | H7: =(h_GAN_DROITS) | I7: =IF(C7<=500,h_PORT_500+h_EMB_PETIT,IF(C7<=1000,h_PORT_1KG+h_EMB_GRAND,h_PORT_2KG+h_EMB_GRAND)) | J7: =h_STRIPE_PCT*D7+h_STRIPE_FIXE | K7: =0 | L7: =0 | M7: =h_PROV_RETOURS*F7 | N7: =0 | O7: =F7-SUM(G7:N7) | P7: =O7/F7 | Q7: =F7/O7 | R7: =D7/O7 | S7: =O7
A8: Site — Raclette seule (+3,90 € de port) | B8: Site | C8: =h_RAC_POIDS | D8: =h_RAC_PRIX+IF(h_RAC_PRIX<h_SEUIL_GRATUIT,h_PORT_CLIENT_TTC,0) | E8: =D8-D8/(1+h_TVA) | F8: =D8-E8 | G8: =(h_RAC_PROD) | H8: =(h_RAC_DROITS) | I8: =IF(C8<=500,h_PORT_500+h_EMB_PETIT,IF(C8<=1000,h_PORT_1KG+h_EMB_GRAND,h_PORT_2KG+h_EMB_GRAND)) | J8: =h_STRIPE_PCT*D8+h_STRIPE_FIXE | K8: =0 | L8: =0 | M8: =h_PROV_RETOURS*F8 | N8: =0 | O8: =F8-SUM(G8:N8) | P8: =O8/F8 | Q8: =F8/O8 | R8: =D8/O8 | S8: =O8
A9: Site — Tapis thermique seul (+3,90 € de port) | B9: Site | C9: =h_TAP_POIDS | D9: =h_TAP_PRIX+IF(h_TAP_PRIX<h_SEUIL_GRATUIT,h_PORT_CLIENT_TTC,0) | E9: =D9-D9/(1+h_TVA) | F9: =D9-E9 | G9: =(h_TAP_PROD) | H9: =(h_TAP_DROITS) | I9: =IF(C9<=500,h_PORT_500+h_EMB_PETIT,IF(C9<=1000,h_PORT_1KG+h_EMB_GRAND,h_PORT_2KG+h_EMB_GRAND)) | J9: =h_STRIPE_PCT*D9+h_STRIPE_FIXE | K9: =0 | L9: =0 | M9: =h_PROV_RETOURS*F9 | N9: =0 | O9: =F9-SUM(G9:N9) | P9: =O9/F9 | Q9: =F9/O9 | R9: =D9/O9 | S9: =O9
A10: Site — Kit anti-poils (+3,90 € de port) | B10: Site | C10: =h_ROU_POIDS+h_GAN_POIDS | D10: =h_KAP_PRIX+IF(h_KAP_PRIX<h_SEUIL_GRATUIT,h_PORT_CLIENT_TTC,0) | E10: =D10-D10/(1+h_TVA) | F10: =D10-E10 | G10: =(h_ROU_PROD+h_GAN_PROD) | H10: =(h_ROU_DROITS+h_GAN_DROITS) | I10: =IF(C10<=500,h_PORT_500+h_EMB_PETIT,IF(C10<=1000,h_PORT_1KG+h_EMB_GRAND,h_PORT_2KG+h_EMB_GRAND)) | J10: =h_STRIPE_PCT*D10+h_STRIPE_FIXE | K10: =0 | L10: =0 | M10: =h_PROV_RETOURS*F10 | N10: =0 | O10: =F10-SUM(G10:N10) | P10: =O10/F10 | Q10: =F10/O10 | R10: =D10/O10 | S10: =O10
A11: Site — Grand kit (port offert) | B11: Site | C11: =h_ROU_POIDS+h_RAC_POIDS+h_GAN_POIDS | D11: =h_GK_PRIX+IF(h_GK_PRIX<h_SEUIL_GRATUIT,h_PORT_CLIENT_TTC,0) | E11: =D11-D11/(1+h_TVA) | F11: =D11-E11 | G11: =(h_ROU_PROD+h_RAC_PROD+h_GAN_PROD) | H11: =(h_ROU_DROITS+h_RAC_DROITS+h_GAN_DROITS) | I11: =IF(C11<=500,h_PORT_500+h_EMB_PETIT,IF(C11<=1000,h_PORT_1KG+h_EMB_GRAND,h_PORT_2KG+h_EMB_GRAND)) | J11: =h_STRIPE_PCT*D11+h_STRIPE_FIXE | K11: =0 | L11: =0 | M11: =h_PROV_RETOURS*F11 | N11: =0 | O11: =F11-SUM(G11:N11) | P11: =O11/F11 | Q11: =F11/O11 | R11: =D11/O11 | S11: =O11
A12: Site — Duo 2 rouleaux (port offert) | B12: Site | C12: =h_ROU_POIDS+h_ROU_POIDS | D12: =h_DUO_PRIX+IF(h_DUO_PRIX<h_SEUIL_GRATUIT,h_PORT_CLIENT_TTC,0) | E12: =D12-D12/(1+h_TVA) | F12: =D12-E12 | G12: =(h_ROU_PROD+h_ROU_PROD) | H12: =(h_ROU_DROITS+h_ROU_DROITS) | I12: =IF(C12<=500,h_PORT_500+h_EMB_PETIT,IF(C12<=1000,h_PORT_1KG+h_EMB_GRAND,h_PORT_2KG+h_EMB_GRAND)) | J12: =h_STRIPE_PCT*D12+h_STRIPE_FIXE | K12: =0 | L12: =0 | M12: =h_PROV_RETOURS*F12 | N12: =0 | O12: =F12-SUM(G12:N12) | P12: =O12/F12 | Q12: =F12/O12 | R12: =D12/O12 | S12: =O12
A13: Site — Kit chat d'hiver (port offert) | B13: Site | C13: =h_ROU_POIDS+h_TAP_POIDS | D13: =h_HIV_PRIX+IF(h_HIV_PRIX<h_SEUIL_GRATUIT,h_PORT_CLIENT_TTC,0) | E13: =D13-D13/(1+h_TVA) | F13: =D13-E13 | G13: =(h_ROU_PROD+h_TAP_PROD) | H13: =(h_ROU_DROITS+h_TAP_DROITS) | I13: =IF(C13<=500,h_PORT_500+h_EMB_PETIT,IF(C13<=1000,h_PORT_1KG+h_EMB_GRAND,h_PORT_2KG+h_EMB_GRAND)) | J13: =h_STRIPE_PCT*D13+h_STRIPE_FIXE | K13: =0 | L13: =0 | M13: =h_PROV_RETOURS*F13 | N13: =0 | O13: =F13-SUM(G13:N13) | P13: =O13/F13 | Q13: =F13/O13 | R13: =D13/O13 | S13: =O13
A14: TikTok Shop, contenu propre — Rouleau | B14: TikTok Shop | C14: =h_ROU_POIDS | D14: =h_ROU_PRIX | E14: =D14-D14/(1+h_TVA) | F14: =D14-E14 | G14: =(h_ROU_PROD) | H14: =(h_ROU_DROITS) | I14: =IF(C14<=500,h_PORT_500+h_EMB_PETIT,IF(C14<=1000,h_PORT_1KG+h_EMB_GRAND,h_PORT_2KG+h_EMB_GRAND)) | J14: =0 | K14: =h_TTS_COMM*D14 | L14: =0 | M14: =h_PROV_RETOURS*F14 | N14: =0 | O14: =F14-SUM(G14:N14) | P14: =O14/F14 | Q14: =F14/O14 | R14: =D14/O14 | S14: =O14
A15: TikTok Shop, contenu propre — Kit anti-poils | B15: TikTok Shop | C15: =h_ROU_POIDS+h_GAN_POIDS | D15: =h_KAP_PRIX | E15: =D15-D15/(1+h_TVA) | F15: =D15-E15 | G15: =(h_ROU_PROD+h_GAN_PROD) | H15: =(h_ROU_DROITS+h_GAN_DROITS) | I15: =IF(C15<=500,h_PORT_500+h_EMB_PETIT,IF(C15<=1000,h_PORT_1KG+h_EMB_GRAND,h_PORT_2KG+h_EMB_GRAND)) | J15: =0 | K15: =h_TTS_COMM*D15 | L15: =0 | M15: =h_PROV_RETOURS*F15 | N15: =0 | O15: =F15-SUM(G15:N15) | P15: =O15/F15 | Q15: =F15/O15 | R15: =D15/O15 | S15: =O15
A16: TikTok Shop, contenu propre, commission 4 % — Rouleau | B16: TikTok Shop | C16: =h_ROU_POIDS | D16: =h_ROU_PRIX | E16: =D16-D16/(1+h_TVA) | F16: =D16-E16 | G16: =(h_ROU_PROD) | H16: =(h_ROU_DROITS) | I16: =IF(C16<=500,h_PORT_500+h_EMB_PETIT,IF(C16<=1000,h_PORT_1KG+h_EMB_GRAND,h_PORT_2KG+h_EMB_GRAND)) | J16: =0 | K16: =h_TTS_COMM_LANCEMENT*D16 | L16: =0 | M16: =h_PROV_RETOURS*F16 | N16: =0 | O16: =F16-SUM(G16:N16) | P16: =O16/F16 | Q16: =F16/O16 | R16: =D16/O16 | S16: =O16
A17: TikTok Shop, affilié 15 % — Rouleau | B17: TikTok Shop | C17: =h_ROU_POIDS | D17: =h_ROU_PRIX | E17: =D17-D17/(1+h_TVA) | F17: =D17-E17 | G17: =(h_ROU_PROD) | H17: =(h_ROU_DROITS) | I17: =IF(C17<=500,h_PORT_500+h_EMB_PETIT,IF(C17<=1000,h_PORT_1KG+h_EMB_GRAND,h_PORT_2KG+h_EMB_GRAND)) | J17: =0 | K17: =h_TTS_COMM*D17 | L17: =h_CREA_COMM*D17 | M17: =h_PROV_RETOURS*F17 | N17: =0 | O17: =F17-SUM(G17:N17) | P17: =O17/F17
A18: TikTok Shop, affilié 15 % — Kit anti-poils | B18: TikTok Shop | C18: =h_ROU_POIDS+h_GAN_POIDS | D18: =h_KAP_PRIX | E18: =D18-D18/(1+h_TVA) | F18: =D18-E18 | G18: =(h_ROU_PROD+h_GAN_PROD) | H18: =(h_ROU_DROITS+h_GAN_DROITS) | I18: =IF(C18<=500,h_PORT_500+h_EMB_PETIT,IF(C18<=1000,h_PORT_1KG+h_EMB_GRAND,h_PORT_2KG+h_EMB_GRAND)) | J18: =0 | K18: =h_TTS_COMM*D18 | L18: =h_CREA_COMM*D18 | M18: =h_PROV_RETOURS*F18 | N18: =0 | O18: =F18-SUM(G18:N18) | P18: =O18/F18
A19: Site — Grand kit si le colis dépasse 500 g emballage compris | B19: Site | C19: =h_ROU_POIDS+h_RAC_POIDS+h_GAN_POIDS | D19: =h_GK_PRIX+IF(h_GK_PRIX<h_SEUIL_GRATUIT,h_PORT_CLIENT_TTC,0) | E19: =D19-D19/(1+h_TVA) | F19: =D19-E19 | G19: =(h_ROU_PROD+h_RAC_PROD+h_GAN_PROD) | H19: =(h_ROU_DROITS+h_RAC_DROITS+h_GAN_DROITS) | I19: =(h_PORT_1KG+h_EMB_GRAND) | J19: =h_STRIPE_PCT*D19+h_STRIPE_FIXE | K19: =0 | L19: =0 | M19: =h_PROV_RETOURS*F19 | N19: =0 | O19: =F19-SUM(G19:N19) | P19: =O19/F19 | Q19: =F19/O19 | R19: =D19/O19 | S19: =O19
A21: Société assujettie — import groupé + 3PL (palier 2)
A22: Cas | B22: Canal | C22: Poids (g) | D22: Prix payé TTC | E22: TVA collectée | F22: CA HT (base) | G22: Coût produit | H22: Droits de douane | I22: Livraison + emballage | J22: Frais de paiement | K22: Commission TikTok Shop | L22: Commission créateur ou pub | M22: Provision retours / litiges | N22: Cotisations micro | O22: Marge de contribution | P22: % du CA HT | Q22: ROAS de rentabilité HT | R22: ROAS de rentabilité TTC | S22: CPA maximal
A23: Site — Rouleau seul | B23: Site | C23: =h_ROU_POIDS | D23: =h_ROU_PRIX+IF(h_ROU_PRIX<h_SEUIL_GRATUIT,h_PORT_CLIENT_TTC,0) | E23: =D23-D23/(1+h_TVA) | F23: =D23-E23 | G23: =h_IMP_ROU | H23: =0 | I23: =IF(C23<=500,h_PORT_500,IF(C23<=1000,h_PORT_1KG,h_PORT_2KG))+h_TPL_PREP | J23: =h_STRIPE_PCT*D23+h_STRIPE_FIXE | K23: =0 | L23: =0 | M23: =h_PROV_RETOURS*F23 | N23: =0 | O23: =F23-SUM(G23:N23) | P23: =O23/F23 | Q23: =F23/O23 | R23: =D23/O23 | S23: =O23
A24: Site — Kit anti-poils | B24: Site | C24: =h_ROU_POIDS+h_GAN_POIDS | D24: =h_KAP_PRIX+IF(h_KAP_PRIX<h_SEUIL_GRATUIT,h_PORT_CLIENT_TTC,0) | E24: =D24-D24/(1+h_TVA) | F24: =D24-E24 | G24: =h_IMP_ROU+h_IMP_GAN | H24: =0 | I24: =IF(C24<=500,h_PORT_500,IF(C24<=1000,h_PORT_1KG,h_PORT_2KG))+h_TPL_PREP | J24: =h_STRIPE_PCT*D24+h_STRIPE_FIXE | K24: =0 | L24: =0 | M24: =h_PROV_RETOURS*F24 | N24: =0 | O24: =F24-SUM(G24:N24) | P24: =O24/F24 | Q24: =F24/O24 | R24: =D24/O24 | S24: =O24
A25: Site — Grand kit | B25: Site | C25: =h_ROU_POIDS+h_RAC_POIDS+h_GAN_POIDS | D25: =h_GK_PRIX+IF(h_GK_PRIX<h_SEUIL_GRATUIT,h_PORT_CLIENT_TTC,0) | E25: =D25-D25/(1+h_TVA) | F25: =D25-E25 | G25: =h_IMP_ROU+h_IMP_RAC+h_IMP_GAN | H25: =0 | I25: =IF(C25<=500,h_PORT_500,IF(C25<=1000,h_PORT_1KG,h_PORT_2KG))+h_TPL_PREP | J25: =h_STRIPE_PCT*D25+h_STRIPE_FIXE | K25: =0 | L25: =0 | M25: =h_PROV_RETOURS*F25 | N25: =0 | O25: =F25-SUM(G25:N25) | P25: =O25/F25 | Q25: =F25/O25 | R25: =D25/O25 | S25: =O25
A26: Site — Duo 2 rouleaux | B26: Site | C26: =h_ROU_POIDS+h_ROU_POIDS | D26: =h_DUO_PRIX+IF(h_DUO_PRIX<h_SEUIL_GRATUIT,h_PORT_CLIENT_TTC,0) | E26: =D26-D26/(1+h_TVA) | F26: =D26-E26 | G26: =h_IMP_ROU+h_IMP_ROU | H26: =0 | I26: =IF(C26<=500,h_PORT_500,IF(C26<=1000,h_PORT_1KG,h_PORT_2KG))+h_TPL_PREP | J26: =h_STRIPE_PCT*D26+h_STRIPE_FIXE | K26: =0 | L26: =0 | M26: =h_PROV_RETOURS*F26 | N26: =0 | O26: =F26-SUM(G26:N26) | P26: =O26/F26 | Q26: =F26/O26 | R26: =D26/O26 | S26: =O26
A27: TikTok Shop, contenu propre — Rouleau | B27: TikTok Shop | C27: =h_ROU_POIDS | D27: =h_ROU_PRIX | E27: =D27-D27/(1+h_TVA) | F27: =D27-E27 | G27: =h_IMP_ROU | H27: =0 | I27: =IF(C27<=500,h_PORT_500,IF(C27<=1000,h_PORT_1KG,h_PORT_2KG))+h_TPL_PREP | J27: =0 | K27: =h_TTS_COMM*D27 | L27: =0 | M27: =h_PROV_RETOURS*F27 | N27: =0 | O27: =F27-SUM(G27:N27) | P27: =O27/F27 | Q27: =F27/O27 | R27: =D27/O27 | S27: =O27
A28: TikTok Shop, contenu propre — Kit anti-poils | B28: TikTok Shop | C28: =h_ROU_POIDS+h_GAN_POIDS | D28: =h_KAP_PRIX | E28: =D28-D28/(1+h_TVA) | F28: =D28-E28 | G28: =h_IMP_ROU+h_IMP_GAN | H28: =0 | I28: =IF(C28<=500,h_PORT_500,IF(C28<=1000,h_PORT_1KG,h_PORT_2KG))+h_TPL_PREP | J28: =0 | K28: =h_TTS_COMM*D28 | L28: =0 | M28: =h_PROV_RETOURS*F28 | N28: =0 | O28: =F28-SUM(G28:N28) | P28: =O28/F28 | Q28: =F28/O28 | R28: =D28/O28 | S28: =O28
A29: TikTok Shop, affilié — Rouleau | B29: TikTok Shop | C29: =h_ROU_POIDS | D29: =h_ROU_PRIX | E29: =D29-D29/(1+h_TVA) | F29: =D29-E29 | G29: =h_IMP_ROU | H29: =0 | I29: =IF(C29<=500,h_PORT_500,IF(C29<=1000,h_PORT_1KG,h_PORT_2KG))+h_TPL_PREP | J29: =0 | K29: =h_TTS_COMM*D29 | L29: =h_CREA_COMM*D29 | M29: =h_PROV_RETOURS*F29 | N29: =0 | O29: =F29-SUM(G29:N29) | P29: =O29/F29
A30: TikTok Shop, affilié — Kit anti-poils | B30: TikTok Shop | C30: =h_ROU_POIDS+h_GAN_POIDS | D30: =h_KAP_PRIX | E30: =D30-D30/(1+h_TVA) | F30: =D30-E30 | G30: =h_IMP_ROU+h_IMP_GAN | H30: =0 | I30: =IF(C30<=500,h_PORT_500,IF(C30<=1000,h_PORT_1KG,h_PORT_2KG))+h_TPL_PREP | J30: =0 | K30: =h_TTS_COMM*D30 | L30: =h_CREA_COMM*D30 | M30: =h_PROV_RETOURS*F30 | N30: =0 | O30: =F30-SUM(G30:N30) | P30: =O30/F30
A31: Site, publicité au CPA réaliste — Grand kit | B31: Site + publicité | C31: =h_ROU_POIDS+h_RAC_POIDS+h_GAN_POIDS | D31: =h_GK_PRIX+IF(h_GK_PRIX<h_SEUIL_GRATUIT,h_PORT_CLIENT_TTC,0) | E31: =D31-D31/(1+h_TVA) | F31: =D31-E31 | G31: =h_IMP_ROU+h_IMP_RAC+h_IMP_GAN | H31: =0 | I31: =IF(C31<=500,h_PORT_500,IF(C31<=1000,h_PORT_1KG,h_PORT_2KG))+h_TPL_PREP | J31: =h_STRIPE_PCT*D31+h_STRIPE_FIXE | K31: =0 | L31: =h_CPA_REALISTE | M31: =h_PROV_RETOURS*F31 | N31: =0 | O31: =F31-SUM(G31:N31) | P31: =O31/F31 | Q31: =F31/(O31+L31) | R31: =D31/(O31+L31) | S31: =(O31+L31)
A32: Site, publicité au CPA optimiste — Grand kit | B32: Site + publicité | C32: =h_ROU_POIDS+h_RAC_POIDS+h_GAN_POIDS | D32: =h_GK_PRIX+IF(h_GK_PRIX<h_SEUIL_GRATUIT,h_PORT_CLIENT_TTC,0) | E32: =D32-D32/(1+h_TVA) | F32: =D32-E32 | G32: =h_IMP_ROU+h_IMP_RAC+h_IMP_GAN | H32: =0 | I32: =IF(C32<=500,h_PORT_500,IF(C32<=1000,h_PORT_1KG,h_PORT_2KG))+h_TPL_PREP | J32: =h_STRIPE_PCT*D32+h_STRIPE_FIXE | K32: =0 | L32: =h_CPA_OPTIMISTE | M32: =h_PROV_RETOURS*F32 | N32: =0 | O32: =F32-SUM(G32:N32) | P32: =O32/F32 | Q32: =F32/(O32+L32) | R32: =D32/(O32+L32) | S32: =(O32+L32)
A34: Société en franchise en base de TVA — micro-stock
A35: Cas | B35: Canal | C35: Poids (g) | D35: Prix payé TTC | E35: TVA collectée | F35: CA HT (base) | G35: Coût produit | H35: Droits de douane | I35: Livraison + emballage | J35: Frais de paiement | K35: Commission TikTok Shop | L35: Commission créateur ou pub | M35: Provision retours / litiges | N35: Cotisations micro | O35: Marge de contribution | P35: % du CA HT | Q35: ROAS de rentabilité HT | R35: ROAS de rentabilité TTC | S35: CPA maximal
A36: Site — Rouleau seul (+3,90 € de port) | B36: Site | C36: =h_ROU_POIDS | D36: =h_ROU_PRIX+IF(h_ROU_PRIX<h_SEUIL_GRATUIT,h_PORT_CLIENT_TTC,0) | E36: =0 | F36: =D36-E36 | G36: =(h_ROU_PROD)*(1+h_TVA) | H36: =(h_ROU_DROITS)*(1+h_TVA) | I36: =IF(C36<=500,h_PORT_500+h_EMB_PETIT,IF(C36<=1000,h_PORT_1KG+h_EMB_GRAND,h_PORT_2KG+h_EMB_GRAND))*(1+h_TVA) | J36: =h_STRIPE_PCT*D36+h_STRIPE_FIXE | K36: =0 | L36: =0 | M36: =h_PROV_RETOURS*F36 | N36: =0 | O36: =F36-SUM(G36:N36) | P36: =O36/F36 | Q36: =F36/O36 | R36: =D36/O36 | S36: =O36
A37: Site — Kit anti-poils (+3,90 € de port) | B37: Site | C37: =h_ROU_POIDS+h_GAN_POIDS | D37: =h_KAP_PRIX+IF(h_KAP_PRIX<h_SEUIL_GRATUIT,h_PORT_CLIENT_TTC,0) | E37: =0 | F37: =D37-E37 | G37: =(h_ROU_PROD+h_GAN_PROD)*(1+h_TVA) | H37: =(h_ROU_DROITS+h_GAN_DROITS)*(1+h_TVA) | I37: =IF(C37<=500,h_PORT_500+h_EMB_PETIT,IF(C37<=1000,h_PORT_1KG+h_EMB_GRAND,h_PORT_2KG+h_EMB_GRAND))*(1+h_TVA) | J37: =h_STRIPE_PCT*D37+h_STRIPE_FIXE | K37: =0 | L37: =0 | M37: =h_PROV_RETOURS*F37 | N37: =0 | O37: =F37-SUM(G37:N37) | P37: =O37/F37 | Q37: =F37/O37 | R37: =D37/O37 | S37: =O37
A38: Site — Grand kit (port offert) | B38: Site | C38: =h_ROU_POIDS+h_RAC_POIDS+h_GAN_POIDS | D38: =h_GK_PRIX+IF(h_GK_PRIX<h_SEUIL_GRATUIT,h_PORT_CLIENT_TTC,0) | E38: =0 | F38: =D38-E38 | G38: =(h_ROU_PROD+h_RAC_PROD+h_GAN_PROD)*(1+h_TVA) | H38: =(h_ROU_DROITS+h_RAC_DROITS+h_GAN_DROITS)*(1+h_TVA) | I38: =IF(C38<=500,h_PORT_500+h_EMB_PETIT,IF(C38<=1000,h_PORT_1KG+h_EMB_GRAND,h_PORT_2KG+h_EMB_GRAND))*(1+h_TVA) | J38: =h_STRIPE_PCT*D38+h_STRIPE_FIXE | K38: =0 | L38: =0 | M38: =h_PROV_RETOURS*F38 | N38: =0 | O38: =F38-SUM(G38:N38) | P38: =O38/F38 | Q38: =F38/O38 | R38: =D38/O38 | S38: =O38
A39: Site — Duo 2 rouleaux (port offert) | B39: Site | C39: =h_ROU_POIDS+h_ROU_POIDS | D39: =h_DUO_PRIX+IF(h_DUO_PRIX<h_SEUIL_GRATUIT,h_PORT_CLIENT_TTC,0) | E39: =0 | F39: =D39-E39 | G39: =(h_ROU_PROD+h_ROU_PROD)*(1+h_TVA) | H39: =(h_ROU_DROITS+h_ROU_DROITS)*(1+h_TVA) | I39: =IF(C39<=500,h_PORT_500+h_EMB_PETIT,IF(C39<=1000,h_PORT_1KG+h_EMB_GRAND,h_PORT_2KG+h_EMB_GRAND))*(1+h_TVA) | J39: =h_STRIPE_PCT*D39+h_STRIPE_FIXE | K39: =0 | L39: =0 | M39: =h_PROV_RETOURS*F39 | N39: =0 | O39: =F39-SUM(G39:N39) | P39: =O39/F39 | Q39: =F39/O39 | R39: =D39/O39 | S39: =O39
A40: TikTok Shop, contenu propre — Rouleau | B40: TikTok Shop | C40: =h_ROU_POIDS | D40: =h_ROU_PRIX | E40: =0 | F40: =D40-E40 | G40: =(h_ROU_PROD)*(1+h_TVA) | H40: =(h_ROU_DROITS)*(1+h_TVA) | I40: =IF(C40<=500,h_PORT_500+h_EMB_PETIT,IF(C40<=1000,h_PORT_1KG+h_EMB_GRAND,h_PORT_2KG+h_EMB_GRAND))*(1+h_TVA) | J40: =0 | K40: =h_TTS_COMM*D40*(1+h_TVA) | L40: =0 | M40: =h_PROV_RETOURS*F40 | N40: =0 | O40: =F40-SUM(G40:N40) | P40: =O40/F40 | Q40: =F40/O40 | R40: =D40/O40 | S40: =O40
A41: TikTok Shop, contenu propre — Kit anti-poils | B41: TikTok Shop | C41: =h_ROU_POIDS+h_GAN_POIDS | D41: =h_KAP_PRIX | E41: =0 | F41: =D41-E41 | G41: =(h_ROU_PROD+h_GAN_PROD)*(1+h_TVA) | H41: =(h_ROU_DROITS+h_GAN_DROITS)*(1+h_TVA) | I41: =IF(C41<=500,h_PORT_500+h_EMB_PETIT,IF(C41<=1000,h_PORT_1KG+h_EMB_GRAND,h_PORT_2KG+h_EMB_GRAND))*(1+h_TVA) | J41: =0 | K41: =h_TTS_COMM*D41*(1+h_TVA) | L41: =0 | M41: =h_PROV_RETOURS*F41 | N41: =0 | O41: =F41-SUM(G41:N41) | P41: =O41/F41 | Q41: =F41/O41 | R41: =D41/O41 | S41: =O41
A42: TikTok Shop, affilié 15 % — Rouleau | B42: TikTok Shop | C42: =h_ROU_POIDS | D42: =h_ROU_PRIX | E42: =0 | F42: =D42-E42 | G42: =(h_ROU_PROD)*(1+h_TVA) | H42: =(h_ROU_DROITS)*(1+h_TVA) | I42: =IF(C42<=500,h_PORT_500+h_EMB_PETIT,IF(C42<=1000,h_PORT_1KG+h_EMB_GRAND,h_PORT_2KG+h_EMB_GRAND))*(1+h_TVA) | J42: =0 | K42: =h_TTS_COMM*D42*(1+h_TVA) | L42: =h_CREA_COMM*D42*(1+h_TVA) | M42: =h_PROV_RETOURS*F42 | N42: =0 | O42: =F42-SUM(G42:N42) | P42: =O42/F42
A43: TikTok Shop, affilié 15 % — Kit anti-poils | B43: TikTok Shop | C43: =h_ROU_POIDS+h_GAN_POIDS | D43: =h_KAP_PRIX | E43: =0 | F43: =D43-E43 | G43: =(h_ROU_PROD+h_GAN_PROD)*(1+h_TVA) | H43: =(h_ROU_DROITS+h_GAN_DROITS)*(1+h_TVA) | I43: =IF(C43<=500,h_PORT_500+h_EMB_PETIT,IF(C43<=1000,h_PORT_1KG+h_EMB_GRAND,h_PORT_2KG+h_EMB_GRAND))*(1+h_TVA) | J43: =0 | K43: =h_TTS_COMM*D43*(1+h_TVA) | L43: =h_CREA_COMM*D43*(1+h_TVA) | M43: =h_PROV_RETOURS*F43 | N43: =0 | O43: =F43-SUM(G43:N43) | P43: =O43/F43
...

Sheet Scénarios 18 mois
A1: Scénarios sur 18 mois (octobre 2026 → mars 2028) — société assujettie à la TVA
A2: Tous les calculs sont des formules. Les saisies (volumes, parts de canal, budgets, frais fixes) sont dans l'onglet Hypothèses. Bénéfice net = avant IS et avant rémunération du dirigeant.
A4: Scénario pessimiste — Porte 1 franchie de justesse ; moins d'une commande par jour hors Noël ; peu d'affiliés actifs ; ni import groupé ni publicité.
A5: Ligne | C5: oct. 2026 | D5: nov. 2026 | E5: déc. 2026 | F5: janv. 2027 | G5: févr. 2027 | H5: mars 2027 | I5: avr. 2027 | J5: mai 2027 | K5: juin 2027 | L5: juil. 2027 | M5: août 2027 | N5: sept. 2027 | O5: oct. 2027 | P5: nov. 2027 | Q5: déc. 2027 | R5: janv. 2028 | S5: févr. 2028 | T5: mars 2028 | U5: Total 18 mois
A6: Exercice | C6: ='Hypothèses'!C144 | D6: ='Hypothèses'!D144 | E6: ='Hypothèses'!E144 | F6: ='Hypothèses'!F144 | G6: ='Hypothèses'!G144 | H6: ='Hypothèses'!H144 | I6: ='Hypothèses'!I144 | J6: ='Hypothèses'!J144 | ... T6: ='Hypothèses'!T144
A7: Commandes site (organique) | C7: ='Hypothèses'!C145*'Hypothèses'!C146 | D7: ='Hypothèses'!D145*'Hypothèses'!D146 | E7: ='Hypothèses'!E145*'Hypothèses'!E146 | F7: ='Hypothèses'!F145*'Hypothèses'!F146 | G7: ='Hypothèses'!G145*'Hypothèses'!G146 | H7: ='Hypothèses'!H145*'Hypothèses'!H146 | I7: ='Hypothèses'!I145*'Hypothèses'!I146 | J7: ='Hypothèses'!J145*'Hypothèses'!J146 | ... T7: ='Hypothèses'!T145*'Hypothèses'!T146 | U7: =SUM(C7:T7)
A8: Commandes TikTok Shop, contenu propre | C8: ='Hypothèses'!C145*'Hypothèses'!C147 | D8: ='Hypothèses'!D145*'Hypothèses'!D147 | E8: ='Hypothèses'!E145*'Hypothèses'!E147 | F8: ='Hypothèses'!F145*'Hypothèses'!F147 | G8: ='Hypothèses'!G145*'Hypothèses'!G147 | H8: ='Hypothèses'!H145*'Hypothèses'!H147 | I8: ='Hypothèses'!I145*'Hypothèses'!I147 | J8: ='Hypothèses'!J145*'Hypothèses'!J147 | ... T8: ='Hypothèses'!T145*'Hypothèses'!T147 | U8: =SUM(C8:T8)
A9: Commandes TikTok Shop, affiliés | C9: ='Hypothèses'!C145*'Hypothèses'!C148 | D9: ='Hypothèses'!D145*'Hypothèses'!D148 | E9: ='Hypothèses'!E145*'Hypothèses'!E148 | F9: ='Hypothèses'!F145*'Hypothèses'!F148 | G9: ='Hypothèses'!G145*'Hypothèses'!G148 | H9: ='Hypothèses'!H145*'Hypothèses'!H148 | I9: ='Hypothèses'!I145*'Hypothèses'!I148 | J9: ='Hypothèses'!J145*'Hypothèses'!J148 | ... T9: ='Hypothèses'!T145*'Hypothèses'!T148 | U9: =SUM(C9:T9)
A10: Commandes issues de la publicité | C10: =IF('Hypothèses'!C152>0,'Hypothèses'!C151/'Hypothèses'!C152,0) | D10: =IF('Hypothèses'!D152>0,'Hypothèses'!D151/'Hypothèses'!D152,0) | E10: =IF('Hypothèses'!E152>0,'Hypothèses'!E151/'Hypothèses'!E152,0) | F10: =IF('Hypothèses'!F152>0,'Hypothèses'!F151/'Hypothèses'!F152,0) | G10: =IF('Hypothèses'!G152>0,'Hypothèses'!G151/'Hypothèses'!G152,0) | H10: =IF('Hypothèses'!H152>0,'Hypothèses'!H151/'Hypothèses'!H152,0) | I10: =IF('Hypothèses'!I152>0,'Hypothèses'!I151/'Hypothèses'!I152,0) | J10: =IF('Hypothèses'!J152>0,'Hypothèses'!J151/'Hypothèses'!J152,0) | ... T10: =IF('Hypothèses'!T152>0,'Hypothèses'!T151/'Hypothèses'!T152,0) | U10: =SUM(C10:T10)
A11: Commandes totales | C11: =C7+C8+C9+C10 | D11: =D7+D8+D9+D10 | E11: =E7+E8+E9+E10 | F11: =F7+F8+F9+F10 | G11: =G7+G8+G9+G10 | H11: =H7+H8+H9+H10 | I11: =I7+I8+I9+I10 | J11: =J7+J8+J9+J10 | ... T11: =T7+T8+T9+T10 | U11: =SUM(C11:T11)
A12: Commandes par jour | C12: =C11/30 | D12: =D11/30 | E12: =E11/30 | F12: =F11/30 | G12: =G11/30 | H12: =H11/30 | I12: =I11/30 | J12: =J11/30 | ... T12: =T11/30
A13: CA TTC | C13: =C7*ue_SITE_TTC+(C8+C9)*ue_TTS_TTC+C10*ue_PUB_TTC | D13: =D7*ue_SITE_TTC+(D8+D9)*ue_TTS_TTC+D10*ue_PUB_TTC | E13: =E7*ue_SITE_TTC+(E8+E9)*ue_TTS_TTC+E10*ue_PUB_TTC | F13: =F7*ue_SITE_TTC+(F8+F9)*ue_TTS_TTC+F10*ue_PUB_TTC | G13: =G7*ue_SITE_TTC+(G8+G9)*ue_TTS_TTC+G10*ue_PUB_TTC | H13: =H7*ue_SITE_TTC+(H8+H9)*ue_TTS_TTC+H10*ue_PUB_TTC | I13: =I7*ue_SITE_TTC+(I8+I9)*ue_TTS_TTC+I10*ue_PUB_TTC | J13: =J7*ue_SITE_TTC+(J8+J9)*ue_TTS_TTC+J10*ue_PUB_TTC | ... T13: =T7*ue_SITE_TTC+(T8+T9)*ue_TTS_TTC+T10*ue_PUB_TTC | U13: =SUM(C13:T13)
A14: CA HT | C14: =C13/(1+h_TVA) | D14: =D13/(1+h_TVA) | E14: =E13/(1+h_TVA) | F14: =F13/(1+h_TVA) | G14: =G13/(1+h_TVA) | H14: =H13/(1+h_TVA) | I14: =I13/(1+h_TVA) | J14: =J13/(1+h_TVA) | ... T14: =T13/(1+h_TVA) | U14: =SUM(C14:T14)
A15: TVA collectée | C15: =C13-C14 | D15: =D13-D14 | E15: =E13-E14 | F15: =F13-F14 | G15: =G13-G14 | H15: =H13-H14 | I15: =I13-I14 | J15: =J13-J14 | ... T15: =T13-T14 | U15: =SUM(C15:T15)
A16: Coût des produits et droits | C16: =C7*IF('Hypothèses'!C150=1,ue_SITE_PROD_IMP,ue_SITE_PROD_MS)+(C8+C9)*IF('Hypothèses'!C150=1,ue_TTS_PROD_IMP,ue_TTS_PROD_MS)+C10*IF('Hypothèses'!C150=1,ue_PUB_PROD_IMP,ue_PUB_PROD_MS) | D16: =D7*IF('Hypothèses'!D150=1,ue_SITE_PROD_IMP,ue_SITE_PROD_MS)+(D8+D9)*IF('Hypothèses'!D150=1,ue_TTS_PROD_IMP,ue_TTS_PROD_MS)+D10*IF('Hypothèses'!D150=1,ue_PUB_PROD_IMP,ue_PUB_PROD_MS) | E16: =E7*IF('Hypothèses'!E150=1,ue_SITE_PROD_IMP,ue_SITE_PROD_MS)+(E8+E9)*IF('Hypothèses'!E150=1,ue_TTS_PROD_IMP,ue_TTS_PROD_MS)+E10*IF('Hypothèses'!E150=1,ue_PUB_PROD_IMP,ue_PUB_PROD_MS) | F16: =F7*IF('Hypothèses'!F150=1,ue_SITE_PROD_IMP,ue_SITE_PROD_MS)+(F8+F9)*IF('Hypothèses'!F150=1,ue_TTS_PROD_IMP,ue_TTS_PROD_MS)+F10*IF('Hypothèses'!F150=1,ue_PUB_PROD_IMP,ue_PUB_PROD_MS) | G16: =G7*IF('Hypothèses'!G150=1,ue_SITE_PROD_IMP,ue_SITE_PROD_MS)+(G8+G9)*IF('Hypothèses'!G150=1,ue_TTS_PROD_IMP,ue_TTS_PROD_MS)+G10*IF('Hypothèses'!G150=1,ue_PUB_PROD_IMP,ue_PUB_PROD_MS) | H16: =H7*IF('Hypothèses'!H150=1,ue_SITE_PROD_IMP,ue_SITE_PROD_MS)+(H8+H9)*IF('Hypothèses'!H150=1,ue_TTS_PROD_IMP,ue_TTS_PROD_MS)+H10*IF('Hypothèses'!H150=1,ue_PUB_PROD_IMP,ue_PUB_PROD_MS) | I16: =I7*IF('Hypothèses'!I150=1,ue_SITE_PROD_IMP,ue_SITE_PROD_MS)+(I8+I9)*IF('Hypothèses'!I150=1,ue_TTS_PROD_IMP,ue_TTS_PROD_MS)+I10*IF('Hypothèses'!I150=1,ue_PUB_PROD_IMP,ue_PUB_PROD_MS) | J16: =J7*IF('Hypothèses'!J150=1,ue_SITE_PROD_IMP,ue_SITE_PROD_MS)+(J8+J9)*IF('Hypothèses'!J150=1,ue_TTS_PROD_IMP,ue_TTS_PROD_MS)+J10*IF('Hypothèses'!J150=1,ue_PUB_PROD_IMP,ue_PUB_PROD_MS) | ... T16: =T7*IF('Hypothèses'!T150=1,ue_SITE_PROD_IMP,ue_SITE_PROD_MS)+(T8+T9)*IF('Hypothèses'!T150=1,ue_TTS_PROD_IMP,ue_TTS_PROD_MS)+T10*IF('Hypothèses'!T150=1,ue_PUB_PROD_IMP,ue_PUB_PROD_MS) | U16: =SUM(C16:T16)
A17: Livraison, emballage, 3PL | C17: =C7*IF('Hypothèses'!C150=1,ue_SITE_LOG_IMP,ue_SITE_LOG_MS)+(C8+C9)*IF('Hypothèses'!C150=1,ue_TTS_LOG_IMP,ue_TTS_LOG_MS)+C10*IF('Hypothèses'!C150=1,ue_PUB_LOG_IMP,ue_PUB_LOG_MS) | D17: =D7*IF('Hypothèses'!D150=1,ue_SITE_LOG_IMP,ue_SITE_LOG_MS)+(D8+D9)*IF('Hypothèses'!D150=1,ue_TTS_LOG_IMP,ue_TTS_LOG_MS)+D10*IF('Hypothèses'!D150=1,ue_PUB_LOG_IMP,ue_PUB_LOG_MS) | E17: =E7*IF('Hypothèses'!E150=1,ue_SITE_LOG_IMP,ue_SITE_LOG_MS)+(E8+E9)*IF('Hypothèses'!E150=1,ue_TTS_LOG_IMP,ue_TTS_LOG_MS)+E10*IF('Hypothèses'!E150=1,ue_PUB_LOG_IMP,ue_PUB_LOG_MS) | F17: =F7*IF('Hypothèses'!F150=1,ue_SITE_LOG_IMP,ue_SITE_LOG_MS)+(F8+F9)*IF('Hypothèses'!F150=1,ue_TTS_LOG_IMP,ue_TTS_LOG_MS)+F10*IF('Hypothèses'!F150=1,ue_PUB_LOG_IMP,ue_PUB_LOG_MS) | G17: =G7*IF('Hypothèses'!G150=1,ue_SITE_LOG_IMP,ue_SITE_LOG_MS)+(G8+G9)*IF('Hypothèses'!G150=1,ue_TTS_LOG_IMP,ue_TTS_LOG_MS)+G10*IF('Hypothèses'!G150=1,ue_PUB_LOG_IMP,ue_PUB_LOG_MS) | H17: =H7*IF('Hypothèses'!H150=1,ue_SITE_LOG_IMP,ue_SITE_LOG_MS)+(H8+H9)*IF('Hypothèses'!H150=1,ue_TTS_LOG_IMP,ue_TTS_LOG_MS)+H10*IF('Hypothèses'!H150=1,ue_PUB_LOG_IMP,ue_PUB_LOG_MS) | I17: =I7*IF('Hypothèses'!I150=1,ue_SITE_LOG_IMP,ue_SITE_LOG_MS)+(I8+I9)*IF('Hypothèses'!I150=1,ue_TTS_LOG_IMP,ue_TTS_LOG_MS)+I10*IF('Hypothèses'!I150=1,ue_PUB_LOG_IMP,ue_PUB_LOG_MS) | J17: =J7*IF('Hypothèses'!J150=1,ue_SITE_LOG_IMP,ue_SITE_LOG_MS)+(J8+J9)*IF('Hypothèses'!J150=1,ue_TTS_LOG_IMP,ue_TTS_LOG_MS)+J10*IF('Hypothèses'!J150=1,ue_PUB_LOG_IMP,ue_PUB_LOG_MS) | ... T17: =T7*IF('Hypothèses'!T150=1,ue_SITE_LOG_IMP,ue_SITE_LOG_MS)+(T8+T9)*IF('Hypothèses'!T150=1,ue_TTS_LOG_IMP,ue_TTS_LOG_MS)+T10*IF('Hypothèses'!T150=1,ue_PUB_LOG_IMP,ue_PUB_LOG_MS) | U17: =SUM(C17:T17)
A18: Frais de paiement | C18: =C7*ue_SITE_PAY+C10*ue_PUB_PAY | D18: =D7*ue_SITE_PAY+D10*ue_PUB_PAY | E18: =E7*ue_SITE_PAY+E10*ue_PUB_PAY | F18: =F7*ue_SITE_PAY+F10*ue_PUB_PAY | G18: =G7*ue_SITE_PAY+G10*ue_PUB_PAY | H18: =H7*ue_SITE_PAY+H10*ue_PUB_PAY | I18: =I7*ue_SITE_PAY+I10*ue_PUB_PAY | J18: =J7*ue_SITE_PAY+J10*ue_PUB_PAY | ... T18: =T7*ue_SITE_PAY+T10*ue_PUB_PAY | U18: =SUM(C18:T18)
A19: Commission TikTok Shop | C19: =(C8+C9)*ue_TTS_TTC*'Hypothèses'!C149 | D19: =(D8+D9)*ue_TTS_TTC*'Hypothèses'!D149 | E19: =(E8+E9)*ue_TTS_TTC*'Hypothèses'!E149 | F19: =(F8+F9)*ue_TTS_TTC*'Hypothèses'!F149 | G19: =(G8+G9)*ue_TTS_TTC*'Hypothèses'!G149 | H19: =(H8+H9)*ue_TTS_TTC*'Hypothèses'!H149 | I19: =(I8+I9)*ue_TTS_TTC*'Hypothèses'!I149 | J19: =(J8+J9)*ue_TTS_TTC*'Hypothèses'!J149 | ... T19: =(T8+T9)*ue_TTS_TTC*'Hypothèses'!T149 | U19: =SUM(C19:T19)
A20: Commission des créateurs | C20: =C9*ue_TTS_TTC*h_CREA_COMM | D20: =D9*ue_TTS_TTC*h_CREA_COMM | E20: =E9*ue_TTS_TTC*h_CREA_COMM | F20: =F9*ue_TTS_TTC*h_CREA_COMM | G20: =G9*ue_TTS_TTC*h_CREA_COMM | H20: =H9*ue_TTS_TTC*h_CREA_COMM | I20: =I9*ue_TTS_TTC*h_CREA_COMM | J20: =J9*ue_TTS_TTC*h_CREA_COMM | ... T20: =T9*ue_TTS_TTC*h_CREA_COMM | U20: =SUM(C20:T20)
A21: Provision retours, SAV, litiges | C21: =h_PROV_RETOURS*C14 | D21: =h_PROV_RETOURS*D14 | E21: =h_PROV_RETOURS*E14 | F21: =h_PROV_RETOURS*F14 | G21: =h_PROV_RETOURS*G14 | H21: =h_PROV_RETOURS*H14 | I21: =h_PROV_RETOURS*I14 | J21: =h_PROV_RETOURS*J14 | ... T21: =h_PROV_RETOURS*T14 | U21: =SUM(C21:T21)
A22: Marge de contribution | C22: =C14-SUM(C16:C21) | D22: =D14-SUM(D16:D21) | E22: =E14-SUM(E16:E21) | F22: =F14-SUM(F16:F21) | G22: =G14-SUM(G16:G21) | H22: =H14-SUM(H16:H21) | I22: =I14-SUM(I16:I21) | J22: =J14-SUM(J16:J21) | ... T22: =T14-SUM(T16:T21) | U22: =SUM(C22:T22)
A23: Publicité | C23: ='Hypothèses'!C151 | D23: ='Hypothèses'!D151 | E23: ='Hypothèses'!E151 | F23: ='Hypothèses'!F151 | G23: ='Hypothèses'!G151 | H23: ='Hypothèses'!H151 | I23: ='Hypothèses'!I151 | J23: ='Hypothèses'!J151 | ... T23: ='Hypothèses'!T151 | U23: =SUM(C23:T23)
A24: Échantillons créateurs | C24: ='Hypothèses'!C153 | D24: ='Hypothèses'!D153 | E24: ='Hypothèses'!E153 | F24: ='Hypothèses'!F153 | G24: ='Hypothèses'!G153 | H24: ='Hypothèses'!H153 | I24: ='Hypothèses'!I153 | J24: ='Hypothèses'!J153 | ... T24: ='Hypothèses'!T153 | U24: =SUM(C24:T24)
A25: Frais fixes et ponctuels | C25: ='Hypothèses'!C157+'Hypothèses'!C158+'Hypothèses'!C159+'Hypothèses'!C160+'Hypothèses'!C161 | D25: ='Hypothèses'!D157+'Hypothèses'!D158+'Hypothèses'!D159+'Hypothèses'!D160+'Hypothèses'!D161 | E25: ='Hypothèses'!E157+'Hypothèses'!E158+'Hypothèses'!E159+'Hypothèses'!E160+'Hypothèses'!E161 | F25: ='Hypothèses'!F157+'Hypothèses'!F158+'Hypothèses'!F159+'Hypothèses'!F160+'Hypothèses'!F161 | G25: ='Hypothèses'!G157+'Hypothèses'!G158+'Hypothèses'!G159+'Hypothèses'!G160+'Hypothèses'!G161 | H25: ='Hypothèses'!H157+'Hypothèses'!H158+'Hypothèses'!H159+'Hypothèses'!H160+'Hypothèses'!H161 | I25: ='Hypothèses'!I157+'Hypothèses'!I158+'Hypothèses'!I159+'Hypothèses'!I160+'Hypothèses'!I161 | J25: ='Hypothèses'!J157+'Hypothèses'!J158+'Hypothèses'!J159+'Hypothèses'!J160+'Hypothèses'!J161 | ... T25: ='Hypothèses'!T157+'Hypothèses'!T158+'Hypothèses'!T159+'Hypothèses'!T160+'Hypothèses'!T161 | U25: =SUM(C25:T25)
A26: Bénéfice net (avant IS et rémunération du dirigeant) | C26: =C22-C23-C24-C25 | D26: =D22-D23-D24-D25 | E26: =E22-E23-E24-E25 | F26: =F22-F23-F24-F25 | G26: =G22-G23-G24-G25 | H26: =H22-H23-H24-H25 | I26: =I22-I23-I24-I25 | J26: =J22-J23-J24-J25 | ... T26: =T22-T23-T24-T25 | U26: =SUM(C26:T26)
A27: Bénéfice net cumulé | C27: =C26 | D27: =D26+C27 | E27: =E26+D27 | F27: =F26+E27 | G27: =G26+F27 | H27: =H26+G27 | I27: =I26+H27 | J27: =J26+I27 | K27: =K26+J27 | ... T27: =T26+S27
A28: Coûts totaux (CA HT − bénéfice net) | C28: =C14-C26 | D28: =D14-D26 | E28: =E14-E26 | F28: =F14-F26 | G28: =G14-G26 | H28: =H14-H26 | I28: =I14-I26 | J28: =J14-J26 | ... T28: =T14-T26 | U28: =SUM(C28:T28)
A29: Nouvel exercice (1 = oui) | C29: =1 | D29: =IF(D6<>C6,1,0) | E29: =IF(E6<>D6,1,0) | F29: =IF(F6<>E6,1,0) | G29: =IF(G6<>F6,1,0) | H29: =IF(H6<>G6,1,0) | I29: =IF(I6<>H6,1,0) | J29: =IF(J6<>I6,1,0) | K29: =IF(K6<>J6,1,0) | ... T29: =IF(T6<>S6,1,0)
A30: Base IS cumulée de l'exercice (déficit antérieur reporté) | C30: =C26 | D30: =IF(D29=1,MIN(0,C30)+D26,C30+D26) | E30: =IF(E29=1,MIN(0,D30)+E26,D30+E26) | F30: =IF(F29=1,MIN(0,E30)+F26,E30+F26) | G30: =IF(G29=1,MIN(0,F30)+G26,F30+G26) | H30: =IF(H29=1,MIN(0,G30)+H26,G30+H26) | I30: =IF(I29=1,MIN(0,H30)+I26,H30+I26) | J30: =IF(J29=1,MIN(0,I30)+J26,I30+J26) | K30: =IF(K29=1,MIN(0,J30)+K26,J30+K26) | ... T30: =IF(T29=1,MIN(0,S30)+T26,S30+T26)
A31: IS cumulé de l'exercice | C31: =h_IS_TAUX_REDUIT*MIN(MAX(C30,0),h_IS_SEUIL)+h_IS_TAUX_NORMAL*MAX(C30-h_IS_SEUIL,0) | D31: =h_IS_TAUX_REDUIT*MIN(MAX(D30,0),h_IS_SEUIL)+h_IS_TAUX_NORMAL*MAX(D30-h_IS_SEUIL,0) | E31: =h_IS_TAUX_REDUIT*MIN(MAX(E30,0),h_IS_SEUIL)+h_IS_TAUX_NORMAL*MAX(E30-h_IS_SEUIL,0) | F31: =h_IS_TAUX_REDUIT*MIN(MAX(F30,0),h_IS_SEUIL)+h_IS_TAUX_NORMAL*MAX(F30-h_IS_SEUIL,0) | G31: =h_IS_TAUX_REDUIT*MIN(MAX(G30,0),h_IS_SEUIL)+h_IS_TAUX_NORMAL*MAX(G30-h_IS_SEUIL,0) | H31: =h_IS_TAUX_REDUIT*MIN(MAX(H30,0),h_IS_SEUIL)+h_IS_TAUX_NORMAL*MAX(H30-h_IS_SEUIL,0) | I31: =h_IS_TAUX_REDUIT*MIN(MAX(I30,0),h_IS_SEUIL)+h_IS_TAUX_NORMAL*MAX(I30-h_IS_SEUIL,0) | J31: =h_IS_TAUX_REDUIT*MIN(MAX(J30,0),h_IS_SEUIL)+h_IS_TAUX_NORMAL*MAX(J30-h_IS_SEUIL,0) | ... T31: =h_IS_TAUX_REDUIT*MIN(MAX(T30,0),h_IS_SEUIL)+h_IS_TAUX_NORMAL*MAX(T30-h_IS_SEUIL,0)
A32: IS du mois (provision) | C32: =C31 | D32: =IF(D29=1,D31,D31-C31) | E32: =IF(E29=1,E31,E31-D31) | F32: =IF(F29=1,F31,F31-E31) | G32: =IF(G29=1,G31,G31-F31) | H32: =IF(H29=1,H31,H31-G31) | I32: =IF(I29=1,I31,I31-H31) | J32: =IF(J29=1,J31,J31-I31) | K32: =IF(K29=1,K31,K31-J31) | ... T32: =IF(T29=1,T31,T31-S31) | U32: =SUM(C32:T32)
A33: Résultat après IS | C33: =C26-C32 | D33: =D26-D32 | E33: =E26-E32 | F33: =F26-F32 | G33: =G26-G32 | H33: =H26-H32 | I33: =I26-I32 | J33: =J26-J32 | ... T33: =T26-T32 | U33: =SUM(C33:T33)
A36: Scénario réaliste — Croissance organique régulière ; palier 1 vers l'été 2027 ; import groupé en octobre 2027 ; test publicitaire de 3 mois arrêté faute de rentabilité.
A37: Ligne | C37: oct. 2026 | D37: nov. 2026 | E37: déc. 2026 | F37: janv. 2027 | G37: févr. 2027 | H37: mars 2027 | I37: avr. 2027 | J37: mai 2027 | K37: juin 2027 | L37: juil. 2027 | M37: août 2027 | N37: sept. 2027 | O37: oct. 2027 | P37: nov. 2027 | Q37: déc. 2027 | R37: janv. 2028 | S37: févr. 2028 | T37: mars 2028 | U37: Total 18 mois
A38: Exercice | C38: ='Hypothèses'!C165 | D38: ='Hypothèses'!D165 | E38: ='Hypothèses'!E165 | F38: ='Hypothèses'!F165 | G38: ='Hypothèses'!G165 | H38: ='Hypothèses'!H165 | I38: ='Hypothèses'!I165 | J38: ='Hypothèses'!J165 | ... T38: ='Hypothèses'!T165
A39: Commandes site (organique) | C39: ='Hypothèses'!C166*'Hypothèses'!C167 | D39: ='Hypothèses'!D166*'Hypothèses'!D167 | E39: ='Hypothèses'!E166*'Hypothèses'!E167 | F39: ='Hypothèses'!F166*'Hypothèses'!F167 | G39: ='Hypothèses'!G166*'Hypothèses'!G167 | H39: ='Hypothèses'!H166*'Hypothèses'!H167 | I39: ='Hypothèses'!I166*'Hypothèses'!I167 | J39: ='Hypothèses'!J166*'Hypothèses'!J167 | ... T39: ='Hypothèses'!T166*'Hypothèses'!T167 | U39: =SUM(C39:T39)
A40: Commandes TikTok Shop, contenu propre | C40: ='Hypothèses'!C166*'Hypothèses'!C168 | D40: ='Hypothèses'!D166*'Hypothèses'!D168 | E40: ='Hypothèses'!E166*'Hypothèses'!E168 | F40: ='Hypothèses'!F166*'Hypothèses'!F168 | G40: ='Hypothèses'!G166*'Hypothèses'!G168 | H40: ='Hypothèses'!H166*'Hypothèses'!H168 | I40: ='Hypothèses'!I166*'Hypothèses'!I168 | J40: ='Hypothèses'!J166*'Hypothèses'!J168 | ... T40: ='Hypothèses'!T166*'Hypothèses'!T168 | U40: =SUM(C40:T40)
A41: Commandes TikTok Shop, affiliés | C41: ='Hypothèses'!C166*'Hypothèses'!C169 | D41: ='Hypothèses'!D166*'Hypothèses'!D169 | E41: ='Hypothèses'!E166*'Hypothèses'!E169 | F41: ='Hypothèses'!F166*'Hypothèses'!F169 | G41: ='Hypothèses'!G166*'Hypothèses'!G169 | H41: ='Hypothèses'!H166*'Hypothèses'!H169 | I41: ='Hypothèses'!I166*'Hypothèses'!I169 | J41: ='Hypothèses'!J166*'Hypothèses'!J169 | ... T41: ='Hypothèses'!T166*'Hypothèses'!T169 | U41: =SUM(C41:T41)
A42: Commandes issues de la publicité | C42: =IF('Hypothèses'!C173>0,'Hypothèses'!C172/'Hypothèses'!C173,0) | D42: =IF('Hypothèses'!D173>0,'Hypothèses'!D172/'Hypothèses'!D173,0) | E42: =IF('Hypothèses'!E173>0,'Hypothèses'!E172/'Hypothèses'!E173,0) | F42: =IF('Hypothèses'!F173>0,'Hypothèses'!F172/'Hypothèses'!F173,0) | G42: =IF('Hypothèses'!G173>0,'Hypothèses'!G172/'Hypothèses'!G173,0) | H42: =IF('Hypothèses'!H173>0,'Hypothèses'!H172/'Hypothèses'!H173,0) | I42: =IF('Hypothèses'!I173>0,'Hypothèses'!I172/'Hypothèses'!I173,0) | J42: =IF('Hypothèses'!J173>0,'Hypothèses'!J172/'Hypothèses'!J173,0) | ... T42: =IF('Hypothèses'!T173>0,'Hypothèses'!T172/'Hypothèses'!T173,0) | U42: =SUM(C42:T42)
A43: Commandes totales | C43: =C39+C40+C41+C42 | D43: =D39+D40+D41+D42 | E43: =E39+E40+E41+E42 | F43: =F39+F40+F41+F42 | G43: =G39+G40+G41+G42 | H43: =H39+H40+H41+H42 | I43: =I39+I40+I41+I42 | J43: =J39+J40+J41+J42 | ... T43: =T39+T40+T41+T42 | U43: =SUM(C43:T43)
...

Sheet Trésorerie
A1: Trésorerie mensuelle — départ à 0 €, fournisseurs payés à la commande
A2: Stripe : 7 jours au premier versement puis 3 jours ouvrés ; TikTok Shop : 31 jours après livraison pour un vendeur débutant, puis 8 jours ; TVA reversée le mois suivant ; stock détenu = couverture × coût des produits du mois suivant.
A4: Scénario pessimiste
A5: Ligne | C5: oct. 2026 | D5: nov. 2026 | E5: déc. 2026 | F5: janv. 2027 | G5: févr. 2027 | H5: mars 2027 | I5: avr. 2027 | J5: mai 2027 | K5: juin 2027 | L5: juil. 2027 | M5: août 2027 | N5: sept. 2027 | O5: oct. 2027 | P5: nov. 2027 | Q5: déc. 2027 | R5: janv. 2028 | S5: févr. 2028 | T5: mars 2028 | U5: Total
A6: Ventes du site nettes de frais de paiement (dues) | C6: ='Scénarios 18 mois'!C7*(ue_SITE_TTC-ue_SITE_PAY)+'Scénarios 18 mois'!C10*(ue_PUB_TTC-ue_PUB_PAY) | D6: ='Scénarios 18 mois'!D7*(ue_SITE_TTC-ue_SITE_PAY)+'Scénarios 18 mois'!D10*(ue_PUB_TTC-ue_PUB_PAY) | E6: ='Scénarios 18 mois'!E7*(ue_SITE_TTC-ue_SITE_PAY)+'Scénarios 18 mois'!E10*(ue_PUB_TTC-ue_PUB_PAY) | F6: ='Scénarios 18 mois'!F7*(ue_SITE_TTC-ue_SITE_PAY)+'Scénarios 18 mois'!F10*(ue_PUB_TTC-ue_PUB_PAY) | G6: ='Scénarios 18 mois'!G7*(ue_SITE_TTC-ue_SITE_PAY)+'Scénarios 18 mois'!G10*(ue_PUB_TTC-ue_PUB_PAY) | H6: ='Scénarios 18 mois'!H7*(ue_SITE_TTC-ue_SITE_PAY)+'Scénarios 18 mois'!H10*(ue_PUB_TTC-ue_PUB_PAY) | I6: ='Scénarios 18 mois'!I7*(ue_SITE_TTC-ue_SITE_PAY)+'Scénarios 18 mois'!I10*(ue_PUB_TTC-ue_PUB_PAY) | J6: ='Scénarios 18 mois'!J7*(ue_SITE_TTC-ue_SITE_PAY)+'Scénarios 18 mois'!J10*(ue_PUB_TTC-ue_PUB_PAY) | ... T6: ='Scénarios 18 mois'!T7*(ue_SITE_TTC-ue_SITE_PAY)+'Scénarios 18 mois'!T10*(ue_PUB_TTC-ue_PUB_PAY)
A7: Encaissement Stripe / Shopify Payments | C7: =C6*(1-'Hypothèses'!C155/30) | D7: =D6*(1-'Hypothèses'!D155/30)+C6*'Hypothèses'!C155/30 | E7: =E6*(1-'Hypothèses'!E155/30)+D6*'Hypothèses'!D155/30 | F7: =F6*(1-'Hypothèses'!F155/30)+E6*'Hypothèses'!E155/30 | G7: =G6*(1-'Hypothèses'!G155/30)+F6*'Hypothèses'!F155/30 | H7: =H6*(1-'Hypothèses'!H155/30)+G6*'Hypothèses'!G155/30 | I7: =I6*(1-'Hypothèses'!I155/30)+H6*'Hypothèses'!H155/30 | J7: =J6*(1-'Hypothèses'!J155/30)+I6*'Hypothèses'!I155/30 | K7: =K6*(1-'Hypothèses'!K155/30)+J6*'Hypothèses'!J155/30 | ... T7: =T6*(1-'Hypothèses'!T155/30)+S6*'Hypothèses'!S155/30 | U7: =SUM(C7:T7)
A8: Ventes TikTok Shop nettes de commissions (dues) | C8: =('Scénarios 18 mois'!C8+'Scénarios 18 mois'!C9)*ue_TTS_TTC*(1-'Hypothèses'!C149)-'Scénarios 18 mois'!C9*ue_TTS_TTC*h_CREA_COMM | D8: =('Scénarios 18 mois'!D8+'Scénarios 18 mois'!D9)*ue_TTS_TTC*(1-'Hypothèses'!D149)-'Scénarios 18 mois'!D9*ue_TTS_TTC*h_CREA_COMM | E8: =('Scénarios 18 mois'!E8+'Scénarios 18 mois'!E9)*ue_TTS_TTC*(1-'Hypothèses'!E149)-'Scénarios 18 mois'!E9*ue_TTS_TTC*h_CREA_COMM | F8: =('Scénarios 18 mois'!F8+'Scénarios 18 mois'!F9)*ue_TTS_TTC*(1-'Hypothèses'!F149)-'Scénarios 18 mois'!F9*ue_TTS_TTC*h_CREA_COMM | G8: =('Scénarios 18 mois'!G8+'Scénarios 18 mois'!G9)*ue_TTS_TTC*(1-'Hypothèses'!G149)-'Scénarios 18 mois'!G9*ue_TTS_TTC*h_CREA_COMM | H8: =('Scénarios 18 mois'!H8+'Scénarios 18 mois'!H9)*ue_TTS_TTC*(1-'Hypothèses'!H149)-'Scénarios 18 mois'!H9*ue_TTS_TTC*h_CREA_COMM | I8: =('Scénarios 18 mois'!I8+'Scénarios 18 mois'!I9)*ue_TTS_TTC*(1-'Hypothèses'!I149)-'Scénarios 18 mois'!I9*ue_TTS_TTC*h_CREA_COMM | J8: =('Scénarios 18 mois'!J8+'Scénarios 18 mois'!J9)*ue_TTS_TTC*(1-'Hypothèses'!J149)-'Scénarios 18 mois'!J9*ue_TTS_TTC*h_CREA_COMM | ... T8: =('Scénarios 18 mois'!T8+'Scénarios 18 mois'!T9)*ue_TTS_TTC*(1-'Hypothèses'!T149)-'Scénarios 18 mois'!T9*ue_TTS_TTC*h_CREA_COMM
A9: Délai d'encaissement TikTok Shop (jours) | C9: ='Hypothèses'!C156 | D9: ='Hypothèses'!D156 | E9: ='Hypothèses'!E156 | F9: ='Hypothèses'!F156 | G9: ='Hypothèses'!G156 | H9: ='Hypothèses'!H156 | I9: ='Hypothèses'!I156 | J9: ='Hypothèses'!J156 | ... T9: ='Hypothèses'!T156
A10: Part encaissée le mois même | C10: =MAX(0,1-C9/30) | D10: =MAX(0,1-D9/30) | E10: =MAX(0,1-E9/30) | F10: =MAX(0,1-F9/30) | G10: =MAX(0,1-G9/30) | H10: =MAX(0,1-H9/30) | I10: =MAX(0,1-I9/30) | J10: =MAX(0,1-J9/30) | ... T10: =MAX(0,1-T9/30)
A11: Part encaissée le mois suivant | C11: =IF(C9<=30,C9/30,(60-C9)/30) | D11: =IF(D9<=30,D9/30,(60-D9)/30) | E11: =IF(E9<=30,E9/30,(60-E9)/30) | F11: =IF(F9<=30,F9/30,(60-F9)/30) | G11: =IF(G9<=30,G9/30,(60-G9)/30) | H11: =IF(H9<=30,H9/30,(60-H9)/30) | I11: =IF(I9<=30,I9/30,(60-I9)/30) | J11: =IF(J9<=30,J9/30,(60-J9)/30) | ... T11: =IF(T9<=30,T9/30,(60-T9)/30)
A12: Part encaissée à M+2 | C12: =MAX(0,(C9-30)/30) | D12: =MAX(0,(D9-30)/30) | E12: =MAX(0,(E9-30)/30) | F12: =MAX(0,(F9-30)/30) | G12: =MAX(0,(G9-30)/30) | H12: =MAX(0,(H9-30)/30) | I12: =MAX(0,(I9-30)/30) | J12: =MAX(0,(J9-30)/30) | ... T12: =MAX(0,(T9-30)/30)
A13: Encaissement TikTok Shop | C13: =C8*C10 | D13: =D8*D10+C8*C11 | E13: =E8*E10+D8*D11+C8*C12 | F13: =F8*F10+E8*E11+D8*D12 | G13: =G8*G10+F8*F11+E8*E12 | H13: =H8*H10+G8*G11+F8*F12 | I13: =I8*I10+H8*H11+G8*G12 | J13: =J8*J10+I8*I11+H8*H12 | K13: =K8*K10+J8*J11+I8*I12 | L13: =L8*L10+K8*K11+J8*J12 | ... T13: =T8*T10+S8*S11+R8*R12 | U13: =SUM(C13:T13)
A14: Total des encaissements | C14: =C7+C13 | D14: =D7+D13 | E14: =E7+E13 | F14: =F7+F13 | G14: =G7+G13 | H14: =H7+H13 | I14: =I7+I13 | J14: =J7+J13 | ... T14: =T7+T13 | U14: =SUM(C14:T14)
A15: Stock en fin de mois (coût HT) | C15: ='Hypothèses'!C154*'Scénarios 18 mois'!D16 | D15: ='Hypothèses'!D154*'Scénarios 18 mois'!E16 | E15: ='Hypothèses'!E154*'Scénarios 18 mois'!F16 | F15: ='Hypothèses'!F154*'Scénarios 18 mois'!G16 | G15: ='Hypothèses'!G154*'Scénarios 18 mois'!H16 | H15: ='Hypothèses'!H154*'Scénarios 18 mois'!I16 | I15: ='Hypothèses'!I154*'Scénarios 18 mois'!J16 | J15: ='Hypothèses'!J154*'Scénarios 18 mois'!K16 | ... S15: ='Hypothèses'!S154*'Scénarios 18 mois'!T16 | T15: ='Hypothèses'!T154*'Scénarios 18 mois'!T16
A16: Achats de stock HT (payés à la commande) | C16: ='Scénarios 18 mois'!C16+C15 | D16: ='Scénarios 18 mois'!D16+D15-C15 | E16: ='Scénarios 18 mois'!E16+E15-D15 | F16: ='Scénarios 18 mois'!F16+F15-E15 | G16: ='Scénarios 18 mois'!G16+G15-F15 | H16: ='Scénarios 18 mois'!H16+H15-G15 | I16: ='Scénarios 18 mois'!I16+I15-H15 | J16: ='Scénarios 18 mois'!J16+J15-I15 | K16: ='Scénarios 18 mois'!K16+K15-J15 | ... T16: ='Scénarios 18 mois'!T16+T15-S15 | U16: =SUM(C16:T16)
A17: Achat en import groupé (TVA autoliquidée, 1 = oui) | C17: ='Hypothèses'!D150 | D17: ='Hypothèses'!E150 | E17: ='Hypothèses'!F150 | F17: ='Hypothèses'!G150 | G17: ='Hypothèses'!H150 | H17: ='Hypothèses'!I150 | I17: ='Hypothèses'!J150 | J17: ='Hypothèses'!K150 | ... S17: ='Hypothèses'!T150 | T17: ='Hypothèses'!T150
A18: TVA payée sur achats de micro-stock | C18: =h_TVA*C16*(1-C17) | D18: =h_TVA*D16*(1-D17) | E18: =h_TVA*E16*(1-E17) | F18: =h_TVA*F16*(1-F17) | G18: =h_TVA*G16*(1-G17) | H18: =h_TVA*H16*(1-H17) | I18: =h_TVA*I16*(1-I17) | J18: =h_TVA*J16*(1-J17) | ... T18: =h_TVA*T16*(1-T17) | U18: =SUM(C18:T18)
A19: Étiquettes, emballage, 3PL (TTC) | C19: ='Scénarios 18 mois'!C17*(1+h_TVA) | D19: ='Scénarios 18 mois'!D17*(1+h_TVA) | E19: ='Scénarios 18 mois'!E17*(1+h_TVA) | F19: ='Scénarios 18 mois'!F17*(1+h_TVA) | G19: ='Scénarios 18 mois'!G17*(1+h_TVA) | H19: ='Scénarios 18 mois'!H17*(1+h_TVA) | I19: ='Scénarios 18 mois'!I17*(1+h_TVA) | J19: ='Scénarios 18 mois'!J17*(1+h_TVA) | ... T19: ='Scénarios 18 mois'!T17*(1+h_TVA) | U19: =SUM(C19:T19)
A20: Publicité | C20: ='Scénarios 18 mois'!C23 | D20: ='Scénarios 18 mois'!D23 | E20: ='Scénarios 18 mois'!E23 | F20: ='Scénarios 18 mois'!F23 | G20: ='Scénarios 18 mois'!G23 | H20: ='Scénarios 18 mois'!H23 | I20: ='Scénarios 18 mois'!I23 | J20: ='Scénarios 18 mois'!J23 | ... T20: ='Scénarios 18 mois'!T23 | U20: =SUM(C20:T20)
A21: Échantillons créateurs | C21: ='Scénarios 18 mois'!C24 | D21: ='Scénarios 18 mois'!D24 | E21: ='Scénarios 18 mois'!E24 | F21: ='Scénarios 18 mois'!F24 | G21: ='Scénarios 18 mois'!G24 | H21: ='Scénarios 18 mois'!H24 | I21: ='Scénarios 18 mois'!I24 | J21: ='Scénarios 18 mois'!J24 | ... T21: ='Scénarios 18 mois'!T24 | U21: =SUM(C21:T21)
A22: Frais fixes et ponctuels | C22: ='Scénarios 18 mois'!C25 | D22: ='Scénarios 18 mois'!D25 | E22: ='Scénarios 18 mois'!E25 | F22: ='Scénarios 18 mois'!F25 | G22: ='Scénarios 18 mois'!G25 | H22: ='Scénarios 18 mois'!H25 | I22: ='Scénarios 18 mois'!I25 | J22: ='Scénarios 18 mois'!J25 | ... T22: ='Scénarios 18 mois'!T25 | U22: =SUM(C22:T22)
A23: Remboursements clients et SAV | C23: ='Scénarios 18 mois'!C21 | D23: ='Scénarios 18 mois'!D21 | E23: ='Scénarios 18 mois'!E21 | F23: ='Scénarios 18 mois'!F21 | G23: ='Scénarios 18 mois'!G21 | H23: ='Scénarios 18 mois'!H21 | I23: ='Scénarios 18 mois'!I21 | J23: ='Scénarios 18 mois'!J21 | ... T23: ='Scénarios 18 mois'!T21 | U23: =SUM(C23:T23)
A24: TVA déductible du mois | C24: =C18+h_TVA*'Scénarios 18 mois'!C17 | D24: =D18+h_TVA*'Scénarios 18 mois'!D17 | E24: =E18+h_TVA*'Scénarios 18 mois'!E17 | F24: =F18+h_TVA*'Scénarios 18 mois'!F17 | G24: =G18+h_TVA*'Scénarios 18 mois'!G17 | H24: =H18+h_TVA*'Scénarios 18 mois'!H17 | I24: =I18+h_TVA*'Scénarios 18 mois'!I17 | J24: =J18+h_TVA*'Scénarios 18 mois'!J17 | ... T24: =T18+h_TVA*'Scénarios 18 mois'!T17
A25: TVA nette reversée (mois suivant) | C25: =0 | D25: ='Scénarios 18 mois'!C15-C24 | E25: ='Scénarios 18 mois'!D15-D24 | F25: ='Scénarios 18 mois'!E15-E24 | G25: ='Scénarios 18 mois'!F15-F24 | H25: ='Scénarios 18 mois'!G15-G24 | I25: ='Scénarios 18 mois'!H15-H24 | J25: ='Scénarios 18 mois'!I15-I24 | K25: ='Scénarios 18 mois'!J15-J24 | ... T25: ='Scénarios 18 mois'!S15-S24 | U25: =SUM(C25:T25)
A26: IS payé (solde 2027 dû en mai 2028, hors horizon) | C26: =0 | D26: =0 | E26: =0 | F26: =0 | G26: =0 | H26: =0 | I26: =0 | J26: =0 | ... T26: =0
A27: Total des décaissements | C27: =C16+C18+C19+C20+C21+C22+C23+C25+C26 | D27: =D16+D18+D19+D20+D21+D22+D23+D25+D26 | E27: =E16+E18+E19+E20+E21+E22+E23+E25+E26 | F27: =F16+F18+F19+F20+F21+F22+F23+F25+F26 | G27: =G16+G18+G19+G20+G21+G22+G23+G25+G26 | H27: =H16+H18+H19+H20+H21+H22+H23+H25+H26 | I27: =I16+I18+I19+I20+I21+I22+I23+I25+I26 | J27: =J16+J18+J19+J20+J21+J22+J23+J25+J26 | ... T27: =T16+T18+T19+T20+T21+T22+T23+T25+T26 | U27: =SUM(C27:T27)
A28: Flux de trésorerie du mois | C28: =C14-C27 | D28: =D14-D27 | E28: =E14-E27 | F28: =F14-F27 | G28: =G14-G27 | H28: =H14-H27 | I28: =I14-I27 | J28: =J14-J27 | ... T28: =T14-T27 | U28: =SUM(C28:T28)
A29: Trésorerie en fin de mois (départ : h_TRESO_INITIALE) | C29: =h_TRESO_INITIALE+C28 | D29: =C29+D28 | E29: =D29+E28 | F29: =E29+F28 | G29: =F29+G28 | H29: =G29+H28 | I29: =H29+I28 | J29: =I29+J28 | K29: =J29+K28 | ... T29: =S29+T28
A30: Besoin de trésorerie (creux le plus bas, signe inversé) | C30: =-MIN(0,MIN(C29:T29))
A33: Scénario réaliste
A34: Ligne | C34: oct. 2026 | D34: nov. 2026 | E34: déc. 2026 | F34: janv. 2027 | G34: févr. 2027 | H34: mars 2027 | I34: avr. 2027 | J34: mai 2027 | K34: juin 2027 | L34: juil. 2027 | M34: août 2027 | N34: sept. 2027 | O34: oct. 2027 | P34: nov. 2027 | Q34: déc. 2027 | R34: janv. 2028 | S34: févr. 2028 | T34: mars 2028 | U34: Total
A35: Ventes du site nettes de frais de paiement (dues) | C35: ='Scénarios 18 mois'!C39*(ue_SITE_TTC-ue_SITE_PAY)+'Scénarios 18 mois'!C42*(ue_PUB_TTC-ue_PUB_PAY) | D35: ='Scénarios 18 mois'!D39*(ue_SITE_TTC-ue_SITE_PAY)+'Scénarios 18 mois'!D42*(ue_PUB_TTC-ue_PUB_PAY) | E35: ='Scénarios 18 mois'!E39*(ue_SITE_TTC-ue_SITE_PAY)+'Scénarios 18 mois'!E42*(ue_PUB_TTC-ue_PUB_PAY) | F35: ='Scénarios 18 mois'!F39*(ue_SITE_TTC-ue_SITE_PAY)+'Scénarios 18 mois'!F42*(ue_PUB_TTC-ue_PUB_PAY) | G35: ='Scénarios 18 mois'!G39*(ue_SITE_TTC-ue_SITE_PAY)+'Scénarios 18 mois'!G42*(ue_PUB_TTC-ue_PUB_PAY) | H35: ='Scénarios 18 mois'!H39*(ue_SITE_TTC-ue_SITE_PAY)+'Scénarios 18 mois'!H42*(ue_PUB_TTC-ue_PUB_PAY) | I35: ='Scénarios 18 mois'!I39*(ue_SITE_TTC-ue_SITE_PAY)+'Scénarios 18 mois'!I42*(ue_PUB_TTC-ue_PUB_PAY) | J35: ='Scénarios 18 mois'!J39*(ue_SITE_TTC-ue_SITE_PAY)+'Scénarios 18 mois'!J42*(ue_PUB_TTC-ue_PUB_PAY) | ... T35: ='Scénarios 18 mois'!T39*(ue_SITE_TTC-ue_SITE_PAY)+'Scénarios 18 mois'!T42*(ue_PUB_TTC-ue_PUB_PAY)
A36: Encaissement Stripe / Shopify Payments | C36: =C35*(1-'Hypothèses'!C176/30) | D36: =D35*(1-'Hypothèses'!D176/30)+C35*'Hypothèses'!C176/30 | E36: =E35*(1-'Hypothèses'!E176/30)+D35*'Hypothèses'!D176/30 | F36: =F35*(1-'Hypothèses'!F176/30)+E35*'Hypothèses'!E176/30 | G36: =G35*(1-'Hypothèses'!G176/30)+F35*'Hypothèses'!F176/30 | H36: =H35*(1-'Hypothèses'!H176/30)+G35*'Hypothèses'!G176/30 | I36: =I35*(1-'Hypothèses'!I176/30)+H35*'Hypothèses'!H176/30 | J36: =J35*(1-'Hypothèses'!J176/30)+I35*'Hypothèses'!I176/30 | K36: =K35*(1-'Hypothèses'!K176/30)+J35*'Hypothèses'!J176/30 | ... T36: =T35*(1-'Hypothèses'!T176/30)+S35*'Hypothèses'!S176/30 | U36: =SUM(C36:T36)
A37: Ventes TikTok Shop nettes de commissions (dues) | C37: =('Scénarios 18 mois'!C40+'Scénarios 18 mois'!C41)*ue_TTS_TTC*(1-'Hypothèses'!C170)-'Scénarios 18 mois'!C41*ue_TTS_TTC*h_CREA_COMM | D37: =('Scénarios 18 mois'!D40+'Scénarios 18 mois'!D41)*ue_TTS_TTC*(1-'Hypothèses'!D170)-'Scénarios 18 mois'!D41*ue_TTS_TTC*h_CREA_COMM | E37: =('Scénarios 18 mois'!E40+'Scénarios 18 mois'!E41)*ue_TTS_TTC*(1-'Hypothèses'!E170)-'Scénarios 18 mois'!E41*ue_TTS_TTC*h_CREA_COMM | F37: =('Scénarios 18 mois'!F40+'Scénarios 18 mois'!F41)*ue_TTS_TTC*(1-'Hypothèses'!F170)-'Scénarios 18 mois'!F41*ue_TTS_TTC*h_CREA_COMM | G37: =('Scénarios 18 mois'!G40+'Scénarios 18 mois'!G41)*ue_TTS_TTC*(1-'Hypothèses'!G170)-'Scénarios 18 mois'!G41*ue_TTS_TTC*h_CREA_COMM | H37: =('Scénarios 18 mois'!H40+'Scénarios 18 mois'!H41)*ue_TTS_TTC*(1-'Hypothèses'!H170)-'Scénarios 18 mois'!H41*ue_TTS_TTC*h_CREA_COMM | I37: =('Scénarios 18 mois'!I40+'Scénarios 18 mois'!I41)*ue_TTS_TTC*(1-'Hypothèses'!I170)-'Scénarios 18 mois'!I41*ue_TTS_TTC*h_CREA_COMM | J37: =('Scénarios 18 mois'!J40+'Scénarios 18 mois'!J41)*ue_TTS_TTC*(1-'Hypothèses'!J170)-'Scénarios 18 mois'!J41*ue_TTS_TTC*h_CREA_COMM | ... T37: =('Scénarios 18 mois'!T40+'Scénarios 18 mois'!T41)*ue_TTS_TTC*(1-'Hypothèses'!T170)-'Scénarios 18 mois'!T41*ue_TTS_TTC*h_CREA_COMM
A38: Délai d'encaissement TikTok Shop (jours) | C38: ='Hypothèses'!C177 | D38: ='Hypothèses'!D177 | E38: ='Hypothèses'!E177 | F38: ='Hypothèses'!F177 | G38: ='Hypothèses'!G177 | H38: ='Hypothèses'!H177 | I38: ='Hypothèses'!I177 | J38: ='Hypothèses'!J177 | ... T38: ='Hypothèses'!T177
A39: Part encaissée le mois même | C39: =MAX(0,1-C38/30) | D39: =MAX(0,1-D38/30) | E39: =MAX(0,1-E38/30) | F39: =MAX(0,1-F38/30) | G39: =MAX(0,1-G38/30) | H39: =MAX(0,1-H38/30) | I39: =MAX(0,1-I38/30) | J39: =MAX(0,1-J38/30) | ... T39: =MAX(0,1-T38/30)
A40: Part encaissée le mois suivant | C40: =IF(C38<=30,C38/30,(60-C38)/30) | D40: =IF(D38<=30,D38/30,(60-D38)/30) | E40: =IF(E38<=30,E38/30,(60-E38)/30) | F40: =IF(F38<=30,F38/30,(60-F38)/30) | G40: =IF(G38<=30,G38/30,(60-G38)/30) | H40: =IF(H38<=30,H38/30,(60-H38)/30) | I40: =IF(I38<=30,I38/30,(60-I38)/30) | J40: =IF(J38<=30,J38/30,(60-J38)/30) | ... T40: =IF(T38<=30,T38/30,(60-T38)/30)
A41: Part encaissée à M+2 | C41: =MAX(0,(C38-30)/30) | D41: =MAX(0,(D38-30)/30) | E41: =MAX(0,(E38-30)/30) | F41: =MAX(0,(F38-30)/30) | G41: =MAX(0,(G38-30)/30) | H41: =MAX(0,(H38-30)/30) | I41: =MAX(0,(I38-30)/30) | J41: =MAX(0,(J38-30)/30) | ... T41: =MAX(0,(T38-30)/30)
A42: Encaissement TikTok Shop | C42: =C37*C39 | D42: =D37*D39+C37*C40 | E42: =E37*E39+D37*D40+C37*C41 | F42: =F37*F39+E37*E40+D37*D41 | G42: =G37*G39+F37*F40+E37*E41 | H42: =H37*H39+G37*G40+F37*F41 | I42: =I37*I39+H37*H40+G37*G41 | J42: =J37*J39+I37*I40+H37*H41 | K42: =K37*K39+J37*J40+I37*I41 | L42: =L37*L39+K37*K40+J37*J41 | ... T42: =T37*T39+S37*S40+R37*R41 | U42: =SUM(C42:T42)
A43: Total des encaissements | C43: =C36+C42 | D43: =D36+D42 | E43: =E36+E42 | F43: =F36+F42 | G43: =G36+G42 | H43: =H36+H42 | I43: =I36+I42 | J43: =J36+J42 | ... T43: =T36+T42 | U43: =SUM(C43:T43)
...

Sheet Paliers
A1: Paliers de bénéfice net mensuel : ce qu'il faut réunir
A2: Paliers 1 et 2 : calcul ascendant à partir des unit economics. Paliers 3 et 4 : calcul descendant à partir d'une marge nette type. Bénéfice net = avant IS et rémunération du dirigeant.
A4: Indicateur | B4: Palier 1 — 1 k€ | C4: Palier 2 — 10 k€ | D4: Palier 3 — 100 k€ | E4: Palier 4 — 1 M€
A5: Bénéfice net visé (€ / mois) | B5: =1000 | C5: =10000 | D5: =100000 | E5: =1000000
A6: Marge par commande après publicité (paliers 1-2) ; bénéfice net par commande (paliers 3-4) (€) | B6: =ue_MIX_MARGE_MS | C6: =(1-h_P2_PART_PUB)*ue_MIX_MARGE_IMP+h_P2_PART_PUB*(ue_PUB_MARGE_AVANT_PUB_IMP-C8) | D6: =D5/D9 | E6: =E5/E9
A7: Frais fixes, personnel et échantillons (€ / mois) | B7: =(h_COMPTABLE+h_BANQUE+h_OUTILS+h_RC+h_DOMICILIATION+h_LEKO/12+h_MEDIATEUR/36+h_DOMAINE/12)+h_P1_ECH | C7: =h_P2_FIXES_AUTRES+h_P2_PERSONNEL+h_P2_ECH
A8: CPA cible (€) | C8: =ue_PUB_MARGE_AVANT_PUB_IMP/h_MER_MARGE
A9: Commandes par mois | B9: =(B5+B7)/B6 | C9: =(C5+C7)/C6 | D9: =D12/h_P3_PANIER | E9: =E12/h_P4_PANIER
A10: Commandes par jour | B10: =B9/30 | C10: =C9/30 | D10: =D9/30 | E10: =E9/30
A11: CA HT nécessaire (€ / mois) | B11: =B9*ue_MIX_HT | C11: =C9*((1-h_P2_PART_PUB)*ue_MIX_HT+h_P2_PART_PUB*ue_PUB_HT) | D11: =D5/h_P3_MARGE | E11: =E5/h_P4_MARGE
A12: CA TTC (€ / mois) | B12: =B9*ue_MIX_TTC | C12: =C9*((1-h_P2_PART_PUB)*ue_MIX_TTC+h_P2_PART_PUB*ue_PUB_TTC) | D12: =D11*(1+h_TVA) | E12: =E11*(1+h_TVA)
A13: Budget publicitaire (€ / mois) | B13: =0 | C13: =C9*h_P2_PART_PUB*C8 | D13: =h_P3_PUB*D11 | E13: =h_P4_PUB*E11
